export const catchError = (fn) => {
  try {
    fn();
  } catch (error) {
    console.log('ðŸ’¥ ERROR: ', error);
  }
};
